Workbook

Sheet Formula list and Reference Docs
A3: Formulas Acronym List | B3: Formula name | C3: FOP | D3: OH-222 (Y/N) | E3: Enovai DOC Reference | F3: Date Updated/Approved | G3: Priority
A4: STONF | B4: Smooth Texture Sugar Free Natural Orange | C4: 90037310 | G4: 1
A5: STOF | B5: Smooth Texture Sugar Free Orange | C5: 15119065 | G5: 3
A6: STOF2 | B6: Smooth Texture Sugar Free Orange Natural Dyes | G6: 2
A7: STOS | B7: Smooth Texture Sugar Orange | C7: 15119088 | G7: 3
A8: STOS2 | B8: Smooth Texture Sugar Orange Natural Dyes | G8: 2
A9: STBF | B9: Smooth Texture Sugar Free Berry | C9: 95636926 | G9: 4
A10: STCFX | B10: Smooth Texture Sugar Free Citrus no Dyes | C10: 21151042 | G10: 1
A11: STCF | B11: Smooth Texture Sugar Free Citrus | C11: 15119066 | G11: 4
A12: OTO | B12: Original Texture Orange | G12: 4
A13: OTR | B13: Original Texture Regular | C13: 15109119 | G13: 1
A14: STR | B14: Smooth Texture Regular | C14: 15104499 | G14: 1
A15: STONFC | B15: Smooth Texture Sugar Free Natural Orange Plus Collagen | C15: 90574821 | G15: 1
A16: STONFV | B16: Smooth Texture Sugar Free Natural Orange Plus Vitamins | C16: 90392894 | G16: 4
A17: STONF2 | B17: Smooth Texture Sugar Free Natural Orange | C17: 90037310
A18: Arches | B18: HPMC capsules
A19: Husky
A20: Saguaro
D21: 10 | E21: mcg/g | F21: 1

Sheet Ingredients
A1: 1 | B1: 2 | C1: 3 | D1: 4 | E1: 5 | F1: 6 | G1: 7 | H1: 8 | I1: 9 | J1: 10 | K1: 11 | L1: 12 | M1: 13 | N1: 14 | O1: 15 | P1: 16 | Q1: 17 | R1: 18 | S1: 19 | T1: 20 | U1: 21 | V1: 22 | W1: 23
A2: Ingredient | B2: Trade Name | C2: CAS | D2: GCAS | E2: kCal (US Rules) | F2: Calories from Fat | G2: Total Fat | H2: Saturated Fat | I2: Trans Fat | J2: Cholesterol | K2: Total carbohydrate | L2: Total dietary fiber | M2: Soluble fiber | N2: Sugar | O2: Added Sugars | P2: Iron | Q2: Potassium | R2: Sodium | S2: Calcium | T2: Vitamin A | U2: Vitamin C | V2: Vitamin D | W2: Protein
A3: Psyllium | B3: Plantaga Ovata | C3: 8063-16-9 | D3: 10047885 | E3: 360.8 | F3: 4.322 | G3: 1.01 | H3: 0.166 | I3: 0 | J3: 0 | K3: 87 | L3: 83.8 | M3: 70.5 | N3: 0.1 | O3: 0 | P3: 7.8 | Q3: 847 | R3: 70.35 | S3: 175.17 | T3: 0 | U3: 0 | W3: 2.101
A4: Maltodextrin | B4: Tate& Lyle Star-Dri 100N-S | C4: 9050-36-6 | D4: 10046056 or 10046057 | E4: 378 | F4: 0 | G4: 0 | H4: 0 | I4: 0 | J4: 0 | K4: 94.2 | L4: 0 | M4: 0 | N4: 3.5 | P4: 0.5 | R4: 150 | S4: 10 | T4: 0 | U4: 0 | W4: 0.3
A5: Citric Acid Anhydrous | C5: 77-92-9 | D5: 10045074 | E5: 247 | F5: 0 | G5: 0 | H5: 0 | I5: 0 | J5: 0 | K5: 99.45 | L5: 0 | M5: 0 | P5: 0 | Q5: 0.3 | R5: 0.3 | S5: 0.2 | T5: 0 | U5: 0 | V5: 0 | W5: 0
A6: Stevia | B6: ADM Stevia RA97 | C6: 58543-16-1 | D6: 91400073 | E6: 0 | F6: 0 | G6: 0 | H6: 0 | I6: 0 | J6: 0 | K6: 0 | L6: 0 | M6: 0 | N6: 0 | O6: 0 | P6: 1.6 | Q6: 4 | R6: 15 | W6: 0
A7: Natural Orange Flavor | B7: E20121886 SENSE CAPTURE ORANGE NATURAL ORANGE FLAVOR WONF | C7: Mixture | D7: 91819530 | E7: 380 | F7: 0 | G7: 0 | H7: 0 | I7: 0 | J7: 0 | K7: 95 | L7: 0 | M7: 0 | N7: 29 | O7: 27 | P7: 0 | Q7: 0 | R7: 50 | S7: 10 | T7: 0 | U7: 0 | V7: 0 | W7: 0
A8: Paprika | B8: MicroCap P-21-WSS-P-125-500 | C8: 68917-78-2 | D8: 91564541 | E8: 494.76 | F8: 192.6 | G8: 21.4 | H8: 3.79 | I8: 0 | J8: 0 | K8: 75.31 | L8: 0 | M8: 0 | N8: 32.05 | O8: 32.05 | P8: 0 | Q8: 2.75 | R8: 0.18 | S8: 0 | T8: 1859.04 | U8: 0.62 | V8: 0 | W8: 0
A9: Turmeric | B9: i-Colors Yellow 901 WSS-P | C9: 84775-52-0 | D9: 91564539 | E9: 320.68 | F9: 0.36 | G9: 0.04 | H9: 0.02 | I9: 0 | J9: 0 | K9: 79.97 | L9: 0 | M9: 0 | N9: 17.05 | O9: 17.05 | P9: 0.09 | Q9: 29.15 | R9: 79.93 | S9: 8.04 | T9: 0 | U9: 0 | V9: 0 | W9: 0
A10: Collagen (Agglomerated) | B10: BCP-500A | D10: 90574833 | E10: 390 | F10: 0 | G10: 0 | H10: 0 | I10: 0 | J10: 0 | K10: 0 | L10: 0 | M10: 0 | N10: 0 | O10: 0 | P10: 3 | Q10: 410 | R10: 240 | S10: 50 | T10: 0 | U10: 0 | V10: 0 | W10: 94
A11: Aspartame | B11: AminoSweet Aspartame | C11: 22839-47-0 | D11: 10045031 | E11: 381 | F11: 0 | G11: 0 | H11: 0 | I11: 0 | J11: 0 | K11: 0 | L11: 0 | M11: 0 | N11: 0 | O11: 0 | P11: 0 | Q11: 10 | R11: 30 | S11: 2 | T11: 0 | U11: 0 | V11: 0 | W11: 95.3
A12: Sugar | B12: Granulated sugar | D12: 10048502 or10048503 | E12: 387 | G12: 0 | H12: 0 | I12: 0 | J12: 0 | K12: 99.8 | L12: 0 | M12: 0 | N12: 99.8 | O12: 99.8 | P12: 0.05 | Q12: 2 | R12: 1 | S12: 1 | T12: 0 | U12: 0 | V12: 0 | W12: 0
A13: Citrus Flavor | B13: Natural and Artificial Orange Flavor 059432 TBHAP0551 | C13: Mixture | D13: 10055913 | E13: 303 | F13: 0 | G13: 0 | H13: 0 | I13: 0 | J13: 0 | K13: 75 | L13: 0 | M13: 0 | N13: 0 | O13: 0 | P13: 0 | Q13: 0 | R13: 160 | S13: 0 | T13: 0 | U13: 0 | V13: 0 | W13: 0
A14: Orange Flavor (Artificial) | B14: Natural and Artificial Orange Flavor 059432 TBHAP0551 | C14: Mixture | D14: 10055911 90629560 | E14: 334 | F14: 0 | G14: 0 | H14: 0 | I14: 0 | J14: 0 | K14: 83.8 | L14: 0.2 | M14: 0 | N14: 2.9 | O14: 0 | P14: 0 | Q14: 8 | R14: 96 | S14: 2 | T14: 0 | U14: 0 | V14: 0 | W14: 0.3
A15: Yellow 6 (FD&IC) | B15: FD&IC Yellow No. 6 | C15: 2783-94-0 | D15: 10045737 | E15: 0 | F15: 0 | G15: 0 | H15: 0 | I15: 0 | J15: 0 | K15: 0 | L15: 0 | M15: 0 | N15: 0 | O15: 0 | P15: 0 | Q15: 0 | R15: 3300 | S15: 0 | T15: 0 | U15: 0 | V15: 0 | W15: 0
A16: NEW Natural Orange Flavor | B16: E25012409 Powerdry PR Orange Natural Orange Flavor WONF | D16: 21346854 | E16: 380 | F16: 0 | G16: 0 | H16: 0 | I16: 0 | J16: 0 | K16: 96 | L16: 0 | M16: 0 | N16: 28 | O16: 28 | P16: 0 | Q16: 0 | R16: 55 | S16: 10 | T16: 0 | U16: 0 | V16: 0 | W16: 0
A17: HPMC Capsules | B17: Capsugel empty hypromellose-based capsule products | D17: 21625430 | E17: 309 | G17: 0.39 | H17: 0.12 | I17: 0.02 | J17: 0 | K17: 0.35 | L17: 94 | N17: 0.35 | P17: 1 | Q17: 122 | R17: 190 | S17: 3 | T17: 0 | U17: 0 | V17: 0 | W17: 0.29
A18: Disco'd | B18: .
A19: Sodium Bicarbonate | B19: Arm & Hammer™Sodium Bicarbonate USP FCC | D19: 91537550 | E19: 0 | F19: 0 | G19: 0 | H19: 0 | I19: 0 | J19: 0 | K19: 0 | L19: 0 | M19: 0 | N19: 0 | O19: 0 | P19: 0.15 | Q19: 0.7 | R19: 27375 | S19: 10 | T19: 0 | U19: 0 | V19: 0 | W19: 0
A20: Malic Acid | D20: 10032129
A21: Ace-K | D21: 95088002
A22: Berry Flavor | D22: 95638082
A23: Pink Lemonade (Natural Lemon) | D23: 95869373
A24: Vitamin Blend | D24: 90402389
A25: Red no. 40 (FD&IC) | D25: 10032185
A26: Blue no. 1(FD&IC) | D26: 10045748
L28: =5*0.84 -> 4.2
C29: For paprika and turmeric, it is only CAS no. of the active in it, not carryovers or impurities)
Q30: Psyllium Potassium levels updated to reflect 6-lot nutritiondata from 2013
A33: Formulas Acronym List | B33: Formula name
A34: STONF | B34: Smooth Texture Sugar Free Natural Orange
A35: STOF | B35: Smooth Texture Sugar Free Orange
A36: STOF2 | B36: Smooth Texture Sugar Free Orange Natural Dyes
A37: STOS | B37: Smooth Texture Sugar Orange
A38: STOS2 | B38: Smooth Texture Sugar Orange Natural Dyes
A39: STBF | B39: Smooth Texture Sugar Free Berry
A40: STCFX | B40: Smooth Texture Sugar Free Citrus no Dyes
A41: STCF | B41: Smooth Texture Sugar Free Citrus
A42: OTO | B42: Original Texture Orange
A43: OTR | B43: Original Texture Regular
...

Sheet COMPARISON
A2: STONF | E2: with | F2: Saguaro
A3: Formulation | B3: =A3&" " &A2 -> Formulation STONF | G3: =A3&" " &F2 -> Formulation Saguaro
A4: Nutrition | B4: =A4&" " &A2 -> Nutrition STONF | G4: =A4&" " &F2 -> Nutrition Saguaro
A5: =VLOOKUP(A2,Ingredients!$A$33:$B$54,2,0) -> Smooth Texture Sugar Free Natural Orange | F5: =VLOOKUP(F2,Ingredients!$A$33:$B$54,2,0) -> Smooth Texture Sugar Free Natural Orange NO DYES
A6: Formula | F6: Formula
A7: Ingredients | B7: Weight % | C7: GCAS | F7: Ingredients | G7: Weight % | H7: GCAS
A8: {=INDIRECT("'"&B$3&"'!B14")} -> Psyllium | B8: {=INDIRECT("'"&B$3&"'!C14")} -> 0.559922 | C8: =VLOOKUP(A8,Ingredients!$A$3:$D$33,4,0) -> 10047885 | F8: {=INDIRECT("'"&G$3&"'!B14")} -> Psyllium | G8: {=INDIRECT("'"&G$3&"'!C14")} -> 0.5626 | H8: =VLOOKUP(F8,Ingredients!$A$3:$D$33,4,0) -> 10047885
A9: {=INDIRECT("'"&B$3&"'!B15")} -> Maltodextrin | B9: {=INDIRECT("'"&B$3&"'!C15")} -> 0.319589 | C9: =VLOOKUP(A9,Ingredients!$A$3:$D$33,4,0) -> 10046056 or 10046057 | F9: {=INDIRECT("'"&G$3&"'!B15")} -> Maltodextrin | G9: {=INDIRECT("'"&G$3&"'!C15")} -> 0.3211 | H9: =VLOOKUP(F9,Ingredients!$A$3:$D$33,4,0) -> 10046056 or 10046057
A10: {=INDIRECT("'"&B$3&"'!B16")} -> Citric Acid Anhydrous | B10: {=INDIRECT("'"&B$3&"'!C16")} -> 0.085019 | C10: =VLOOKUP(A10,Ingredients!$A$3:$D$33,4,0) -> 10045074 | F10: {=INDIRECT("'"&G$3&"'!B16")} -> Citric Acid Anhydrous | G10: {=INDIRECT("'"&G$3&"'!C16")} -> 0.0854 | H10: =VLOOKUP(F10,Ingredients!$A$3:$D$33,4,0) -> 10045074
A11: {=INDIRECT("'"&B$3&"'!B17")} -> Stevia | B11: {=INDIRECT("'"&B$3&"'!C17")} -> 0.007428 | C11: =VLOOKUP(A11,Ingredients!$A$3:$D$33,4,0) -> 91400073 | F11: {=INDIRECT("'"&G$3&"'!B17")} -> Stevia | G11: {=INDIRECT("'"&G$3&"'!C17")} -> 0.0075 | H11: =VLOOKUP(F11,Ingredients!$A$3:$D$33,4,0) -> 91400073
A12: {=INDIRECT("'"&B$3&"'!B18")} -> NEW Natural Orange Flavor | B12: {=INDIRECT("'"&B$3&"'!C18")} -> 0.023207 | C12: =VLOOKUP(A12,Ingredients!$A$3:$D$33,4,0) -> 21346854 | F12: {=INDIRECT("'"&G$3&"'!B18")} -> NEW Natural Orange Flavor | G12: {=INDIRECT("'"&G$3&"'!C18")} -> 0.0233 | H12: =VLOOKUP(F12,Ingredients!$A$3:$D$33,4,0) -> 21346854
A13: {=INDIRECT("'"&B$3&"'!B19")} -> Paprika | B13: {=INDIRECT("'"&B$3&"'!C19")} -> 0.003516 | C13: =VLOOKUP(A13,Ingredients!$A$3:$D$33,4,0) -> 91564541 | F13: {=INDIRECT("'"&G$3&"'!B19")} -> 0 | G13: {=INDIRECT("'"&G$3&"'!C19")} -> 0 | H13: =VLOOKUP(F13,Ingredients!$A$3:$D$33,4,0) -> #N/A
A14: {=INDIRECT("'"&B$3&"'!B20")} -> Turmeric | B14: {=INDIRECT("'"&B$3&"'!C20")} -> 0.001319 | C14: =VLOOKUP(A14,Ingredients!$A$3:$D$33,4,0) -> 91564539 | F14: {=INDIRECT("'"&G$3&"'!B20")} -> 0 | G14: {=INDIRECT("'"&G$3&"'!C20")} -> 0 | H14: =VLOOKUP(F14,Ingredients!$A$3:$D$33,4,0) -> #N/A
A15: {=INDIRECT("'"&B$3&"'!B21")} -> 0 | B15: {=INDIRECT("'"&B$3&"'!C21")} -> 0 | C15: =VLOOKUP(A15,Ingredients!$A$3:$D$33,4,0) -> #N/A | F15: {=INDIRECT("'"&G$3&"'!B121")} -> 0 | G15: {=INDIRECT("'"&G$3&"'!C21")} -> 0 | H15: =VLOOKUP(F15,Ingredients!$A$3:$D$33,4,0) -> #N/A
A16: {=INDIRECT("'"&B$3&"'!B122")} -> 0 | B16: {=INDIRECT("'"&B$3&"'!C22")} -> 0 | C16: =VLOOKUP(A16,Ingredients!$A$3:$D$33,4,0) -> #N/A | F16: {=INDIRECT("'"&G$3&"'!B122")} -> 0 | G16: {=INDIRECT("'"&G$3&"'!C22")} -> 0 | H16: =VLOOKUP(F16,Ingredients!$A$3:$D$33,4,0) -> #N/A
A17: {=INDIRECT("'"&B$3&"'!B123")} -> 0 | B17: {=INDIRECT("'"&B$3&"'!C23")} -> 0 | C17: =VLOOKUP(A17,Ingredients!$A$3:$D$33,4,0) -> #N/A | F17: {=INDIRECT("'"&G$3&"'!B123")} -> 0 | G17: {=INDIRECT("'"&G$3&"'!C23")} -> 0 | H17: =VLOOKUP(F17,Ingredients!$A$3:$D$33,4,0) -> #N/A
A18: {=INDIRECT("'"&B$3&"'!B124")} -> 0 | B18: {=INDIRECT("'"&B$3&"'!C24")} -> 0 | C18: =VLOOKUP(A18,Ingredients!$A$3:$D$33,4,0) -> #N/A | F18: {=INDIRECT("'"&G$3&"'!B124")} -> 0 | G18: {=INDIRECT("'"&G$3&"'!C24")} -> 0 | H18: =VLOOKUP(F18,Ingredients!$A$3:$D$33,4,0) -> #N/A
A19: {=INDIRECT("'"&B$3&"'!B125")} -> 0 | B19: {=INDIRECT("'"&B$3&"'!C25")} -> 0 | C19: =VLOOKUP(A19,Ingredients!$A$3:$D$33,4,0) -> #N/A | F19: {=INDIRECT("'"&G$3&"'!B125")} -> 0 | G19: {=INDIRECT("'"&G$3&"'!C25")} -> 0 | H19: =VLOOKUP(F19,Ingredients!$A$3:$D$33,4,0) -> #N/A
A20: {=INDIRECT("'"&B$3&"'!B126")} -> 0 | B20: {=INDIRECT("'"&B$3&"'!C26")} -> 0 | C20: =VLOOKUP(A20,Ingredients!$A$3:$D$33,4,0) -> #N/A | F20: {=INDIRECT("'"&G$3&"'!B126")} -> 0 | G20: {=INDIRECT("'"&G$3&"'!C26")} -> 0 | H20: =VLOOKUP(F20,Ingredients!$A$3:$D$33,4,0) -> #N/A
B21: =SUM(B8:B20) -> 1 | G21: =SUM(G8:G20) -> 0.9999
A22: Dose Size | B22: {=INDIRECT("'"&B$3&"'!C7")} -> 5.8272 | C22: g | F22: Dose Size | G22: {=INDIRECT("'"&G$3&"'!C7")} -> 6.6 | H22: g
A23: Nutrition | C23: units | D23: label rec | F23: Nutrition | H23: units | I23: label rec
A24: {=INDIRECT("'"&B$4&"'!C9")} -> Total carbohydrate | B24: {=INDIRECT("'"&B$4&"'!C10")} -> 5.2370083 | C24: g | D24: {=INDIRECT("'"&B$4&"'!C14")} -> 5g | F24: {=INDIRECT("'"&G$4&"'!C9")} -> Total carbohydrate | G24: {=INDIRECT("'"&G$4&"'!C10")} -> 5.9349609 | H24: g | I24: {=INDIRECT("'"&G$4&"'!C14")} -> 6g
A25: {=INDIRECT("'"&B$4&"'!D9")} -> Total dietary fiber | B25: {=INDIRECT("'"&B$4&"'!D10")} -> 2.7342075 | C25: g | D25: {=INDIRECT("'"&B$4&"'!D14")} -> 3g | F25: {=INDIRECT("'"&G$4&"'!D9")} -> Total dietary fiber | G25: {=INDIRECT("'"&G$4&"'!D10")} -> 3.1116281 | H25: g | I25: {=INDIRECT("'"&G$4&"'!D14")} -> 3g
A26: {=INDIRECT("'"&B$4&"'!E9")} -> Soluble fiber | B26: {=INDIRECT("'"&B$4&"'!E10")} -> 2.3002581 | C26: g | D26: {=INDIRECT("'"&B$4&"'!E14")} -> 2g | F26: {=INDIRECT("'"&G$4&"'!E9")} -> Soluble fiber | G26: {=INDIRECT("'"&G$4&"'!E10")} -> 2.6177778 | H26: g | I26: {=INDIRECT("'"&G$4&"'!E14")} -> 3g
A27: {=INDIRECT("'"&B$4&"'!C16")} -> Iron [Mandatory] | B27: {=INDIRECT("'"&B$4&"'!C17")} -> 0.26450766 | C27: mg | D27: {=INDIRECT("'"&B$4&"'!C21")} -> 2% DV | F27: {=INDIRECT("'"&G$4&"'!C16")} -> Iron [Mandatory] | G27: {=INDIRECT("'"&G$4&"'!C17")} -> 0.30101478 | H27: mg | I27: {=INDIRECT("'"&G$4&"'!C21")} -> 2% DV
A28: {=INDIRECT("'"&B$4&"'!D16")} -> Potassium [Mandatory] | B28: {=INDIRECT("'"&B$4&"'!D17")} -> 27.641747 | C28: mg | D28: {=INDIRECT("'"&B$4&"'!D21")} -> 30 mg | F28: {=INDIRECT("'"&G$4&"'!D16")} -> Potassium [Mandatory] | G28: {=INDIRECT("'"&G$4&"'!D17")} -> 31.454136 | H28: mg | I28: {=INDIRECT("'"&G$4&"'!D21")} -> 30 mg
A29: {=INDIRECT("'"&B$4&"'!E16")} -> Calcium [Mandatory] | B29: {=INDIRECT("'"&B$4&"'!E17")} -> 5.9167702 | C29: mg | D29: {=INDIRECT("'"&B$4&"'!E21")} -> 0 | F29: {=INDIRECT("'"&G$4&"'!E16")} -> Calcium [Mandatory] | G29: {=INDIRECT("'"&G$4&"'!E17")} -> 6.7327737 | H29: mg | I29: {=INDIRECT("'"&G$4&"'!E21")} -> 0
A30: {=INDIRECT("'"&B$4&"'!C23")} -> Vitamin A [Voluntary] | B30: {=INDIRECT("'"&B$4&"'!C24")} -> 0.38088821 | C30: IU | D30: {=INDIRECT("'"&B$4&"'!C21")} -> 2% DV | F30: {=INDIRECT("'"&G$4&"'!C23")} -> Vitamin A [Voluntary] | G30: {=INDIRECT("'"&G$4&"'!C24")} -> 0 | H30: IU | I30: {=INDIRECT("'"&G$4&"'!C21")} -> 2% DV
A31: {=INDIRECT("'"&B$4&"'!D23")} -> Vitamin C [Voluntary] | B31: {=INDIRECT("'"&B$4&"'!D24")} -> 0.0001270283 | C31: mg | D31: {=INDIRECT("'"&B$4&"'!D28")} -> none | F31: {=INDIRECT("'"&G$4&"'!D23")} -> Vitamin C [Voluntary] | G31: {=INDIRECT("'"&G$4&"'!D24")} -> 0 | H31: mg | I31: {=INDIRECT("'"&G$4&"'!D28")} -> none
A32: {=INDIRECT("'"&B$4&"'!E23")} -> Vitamin D [Mandatory] | B32: {=INDIRECT("'"&B$4&"'!E24")} -> 0 | C32: mcg | D32: {=INDIRECT("'"&B$4&"'!E28")} -> 0 | F32: {=INDIRECT("'"&G$4&"'!E23")} -> Vitamin D [Mandatory] | G32: {=INDIRECT("'"&G$4&"'!E24")} -> 0 | H32: mcg | I32: {=INDIRECT("'"&G$4&"'!E28")} -> 0
A33: {=INDIRECT("'"&B$4&"'!f23")} -> Protein | B33: {=INDIRECT("'"&B$4&"'!F24")} -> 0.074137882 | C33: mg | D33: {=INDIRECT("'"&B$4&"'!F28")} -> 0g | F33: {=INDIRECT("'"&G$4&"'!f23")} -> Protein | G33: {=INDIRECT("'"&G$4&"'!F24")} -> 0.084371272 | H33: mg | I33: {=INDIRECT("'"&G$4&"'!F28")} -> 0g
A34: {=INDIRECT("'"&B$4&"'!C30")} -> Total Fat | B34: {=INDIRECT("'"&B$4&"'!C31")} -> 0.037341652 | C34: g | D34: {=INDIRECT("'"&B$4&"'!C35")} -> none | F34: {=INDIRECT("'"&G$4&"'!C30")} -> Total Fat | G34: {=INDIRECT("'"&G$4&"'!C31")} -> 0.037502916 | H34: g | I34: {=INDIRECT("'"&G$4&"'!C35")} -> none
A35: {=INDIRECT("'"&B$4&"'!D30")} -> Saturated Fat | B35: {=INDIRECT("'"&B$4&"'!D31")} -> 0.0061942595 | C35: g | D35: {=INDIRECT("'"&B$4&"'!D35")} -> none | F35: {=INDIRECT("'"&G$4&"'!D30")} -> Saturated Fat | G35: {=INDIRECT("'"&G$4&"'!D31")} -> 0.0061638456 | H35: g | I35: {=INDIRECT("'"&G$4&"'!D35")} -> none
A36: {=INDIRECT("'"&B$4&"'!E30")} -> Trans Fat | B36: {=INDIRECT("'"&B$4&"'!E31")} -> 0 | C36: g | D36: {=INDIRECT("'"&B$4&"'!E35")} -> none | F36: {=INDIRECT("'"&G$4&"'!E30")} -> Trans Fat | G36: {=INDIRECT("'"&G$4&"'!E31")} -> 0 | H36: g | I36: {=INDIRECT("'"&G$4&"'!E35")} -> none
A37: {=INDIRECT("'"&B$4&"'!f30")} -> Cholesterol | B37: {=INDIRECT("'"&B$4&"'!f31")} -> 0 | C37: mg | D37: {=INDIRECT("'"&B$4&"'!f35")} -> none | F37: {=INDIRECT("'"&G$4&"'!f30")} -> Cholesterol | G37: {=INDIRECT("'"&G$4&"'!f31")} -> 0 | H37: mg | I37: {=INDIRECT("'"&G$4&"'!f35")} -> none
A38: {=INDIRECT("'"&B$4&"'!C37")} -> Calories (US Rules) | B38: {=INDIRECT("'"&B$4&"'!C38")} -> 15.244346 | C38: kCal | D38: {=INDIRECT("'"&B$4&"'!C42")} -> 15kCal | F38: {=INDIRECT("'"&G$4&"'!C37")} -> Calories (US Rules) | G38: {=INDIRECT("'"&G$4&"'!C38")} -> 17.203898 | H38: kCal | I38: {=INDIRECT("'"&G$4&"'!C42")} -> 15kCal
A39: {=INDIRECT("'"&B$4&"'!D37")} -> Calories from Fat | B39: {=INDIRECT("'"&B$4&"'!D38")} -> 0.18050564 | C39: kCal | D39: {=INDIRECT("'"&B$4&"'!D42")} -> none | F39: {=INDIRECT("'"&G$4&"'!D37")} -> Calories from Fat | G39: {=INDIRECT("'"&G$4&"'!D38")} -> 0.16048278 | H39: kCal | I39: {=INDIRECT("'"&G$4&"'!D42")} -> none
A40: {=INDIRECT("'"&B$4&"'!E37")} -> Sugar | B40: {=INDIRECT("'"&B$4&"'!E38")} -> 0.11418553 | C40: g | D40: {=INDIRECT("'"&B$4&"'!E42")} -> 0 | F40: {=INDIRECT("'"&G$4&"'!E37")} -> Sugar | G40: {=INDIRECT("'"&G$4&"'!E38")} -> 0.12094566 | H40: g | I40: {=INDIRECT("'"&G$4&"'!E42")} -> 0
A41: {=INDIRECT("'"&B$4&"'!f37")} -> Added Sugars | B41: {=INDIRECT("'"&B$4&"'!f38")} -> 0.045741932 | C41: g | D41: {=INDIRECT("'"&B$4&"'!f42")} -> 0 | F41: {=INDIRECT("'"&G$4&"'!f37")} -> Added Sugars | G41: {=INDIRECT("'"&G$4&"'!f38")} -> 0.0430584 | H41: g | I41: {=INDIRECT("'"&G$4&"'!f42")} -> 0
...

Sheet Formulation STONF
B1: Edited/created on | C1: 46078 | D1: By | E1: Brooke Baker | F1: for | G1: Project 5-way
B2: Pick list items in blue
B3: edit yellow/orange cells
B4: green are results
B5: Product | C5: GCAS | D5: STONF
B6: Smooth Texture Sugar Free Orange Natural Dyes | C6: 5.8272 | D6: =C6*2 -> 11.6544
B7: DRIVER (g weight) | C7: =C6 -> 5.8272 | E7: US rules (C) with sol. Fiber
B8: Total = | C8: =SUM(C14:C34) -> 1 | D8: =SUM(D14:D21) -> 5.8272 | E8: ='Nutrition STOF'!C7 -> 30.349742 | F8: =SUM(F14:F34) -> 0.18050564 | G8: =SUM(G14:G34) -> 0.037341652 | H8: =SUM(H14:H34) -> 0.0061942595 | I8: =SUM(I14:I34) -> 0 | J8: =SUM(J14:J34) -> 0 | K8: =SUM(K14:K34) -> 5.2370083 | L8: =SUM(L14:L34) -> 2.7342075 | M8: =SUM(M14:M34) -> 2.3002581 | ... W8: =SUM(W14:W34) -> 0.074137882
E9: add g, mg, IU, ncg / 100 g row
B10: servings | C10: 2 | D10: =C6*2 -> 11.6544 | E10: =E8*$C$10 -> 60.699483 | F10: =F8*$C$10 -> 0.36101128 | G10: =G8*$C$10 -> 0.074683304 | H10: =H8*$C$10 -> 0.012388519 | I10: =I8*$C$10 -> 0 | J10: =J8*$C$10 -> 0 | K10: =K8*$C$10 -> 10.474017 | L10: =L8*$C$10 -> 5.4684151 | ... W10: =W8*$C$10 -> 0.14827576
C12: =SUM(C14:C34) -> 1
B13: Ingredient | C13: % w/w | D13: Dose wt | E13: Calories (US Rules) | F13: Calories from Fat | G13: Total Fat | H13: Saturated Fat | I13: Trans Fat | J13: Cholesterol | K13: Total carbohydrate | L13: Total dietary fiber | M13: Soluble fiber | N13: Sugar | O13: Added Sugars | P13: Iron | Q13: Potassium | R13: Sodium | S13: Calcium | T13: Vitamin A | U13: Vitamin C | V13: Vitamin D | W13: Protein
A14: 1 | B14: Psyllium | C14: 0.559922 | D14: =C14*$C$7 -> 3.2627775 | E14: =VLOOKUP($B14,Ingredients!$A:$W,5,FALSE)*$D14/100 -> 11.772101 | F14: =VLOOKUP($B14,Ingredients!$A:$W,6,FALSE)*$D14/100 -> 0.14101724 | G14: =VLOOKUP($B14,Ingredients!$A:$W,7,FALSE)*$D14/100 -> 0.032954053 | H14: =VLOOKUP($B14,Ingredients!$A:$W,8,FALSE)*$D14/100 -> 0.0054162106 | I14: =VLOOKUP($B14,Ingredients!$A:$W,9,FALSE)*$D14/100 -> 0 | J14: =VLOOKUP($B14,Ingredients!$A:$W,10,FALSE)*$D14/100 -> 0 | K14: =VLOOKUP($B14,Ingredients!$A:$W,11,FALSE)*$D14/100 -> 2.8386164 | L14: =VLOOKUP($B14,Ingredients!$A:$W,12,FALSE)*$D14/100 -> 2.7342075 | M14: =VLOOKUP($B14,Ingredients!$A:$W,13,FALSE)*$D14/100 -> 2.3002581 | N14: =VLOOKUP($B14,Ingredients!$A:$W,14,FALSE)*$D14/100 -> 0.0032627775 | O14: =VLOOKUP($B14,Ingredients!$A:$W,15,FALSE)*$D14/100 -> 0 | P14: =VLOOKUP($B14,Ingredients!$A:$W,16,FALSE)*$D14/100 -> 0.25449664 | Q14: =VLOOKUP($B14,Ingredients!$A:$W,17,FALSE)*$D14/100 -> 27.635725 | R14: =VLOOKUP($B14,Ingredients!$A:$W,18,FALSE)*$D14/100 -> 2.295364 | S14: =VLOOKUP($B14,Ingredients!$A:$W,19,FALSE)*$D14/100 -> 5.7154073 | T14: =VLOOKUP($B14,Ingredients!$A:$W,20,FALSE)*$D14/100 -> 0 | U14: =VLOOKUP($B14,Ingredients!$A:$W,21,FALSE)*$D14/100 -> 0 | V14: =VLOOKUP($B14,Ingredients!$A:$W,22,FALSE)*$D14/100 -> 0 | W14: =VLOOKUP($B14,Ingredients!$A:$W,23,FALSE)*$D14/100 -> 0.068550955
A15: 2 | B15: Maltodextrin | C15: 0.319589 | D15: =C15*$C$7 -> 1.862309 | E15: =VLOOKUP($B15,Ingredients!$A:$W,5,FALSE)*$D15/100 -> 7.0395281 | F15: =VLOOKUP($B15,Ingredients!$A:$W,6,FALSE)*$D15/100 -> 0 | G15: =VLOOKUP($B15,Ingredients!$A:$W,7,FALSE)*$D15/100 -> 0 | H15: =VLOOKUP($B15,Ingredients!$A:$W,8,FALSE)*$D15/100 -> 0 | I15: =VLOOKUP($B15,Ingredients!$A:$W,9,FALSE)*$D15/100 -> 0 | J15: =VLOOKUP($B15,Ingredients!$A:$W,10,FALSE)*$D15/100 -> 0 | K15: =VLOOKUP($B15,Ingredients!$A:$W,11,FALSE)*$D15/100 -> 1.7542951 | L15: =VLOOKUP($B15,Ingredients!$A:$W,12,FALSE)*$D15/100 -> 0 | M15: =VLOOKUP($B15,Ingredients!$A:$W,13,FALSE)*$D15/100 -> 0 | N15: =VLOOKUP($B15,Ingredients!$A:$W,14,FALSE)*$D15/100 -> 0.065180816 | O15: =VLOOKUP($B15,Ingredients!$A:$W,15,FALSE)*$D15/100 -> 0 | P15: =VLOOKUP($B15,Ingredients!$A:$W,16,FALSE)*$D15/100 -> 0.0093115451 | Q15: =VLOOKUP($B15,Ingredients!$A:$W,17,FALSE)*$D15/100 -> 0 | R15: =VLOOKUP($B15,Ingredients!$A:$W,18,FALSE)*$D15/100 -> 2.7934635 | S15: =VLOOKUP($B15,Ingredients!$A:$W,19,FALSE)*$D15/100 -> 0.1862309 | T15: =VLOOKUP($B15,Ingredients!$A:$W,20,FALSE)*$D15/100 -> 0 | U15: =VLOOKUP($B15,Ingredients!$A:$W,21,FALSE)*$D15/100 -> 0 | V15: =VLOOKUP($B15,Ingredients!$A:$W,22,FALSE)*$D15/100 -> 0 | W15: =VLOOKUP($B15,Ingredients!$A:$W,23,FALSE)*$D15/100 -> 0.0055869271
A16: 3 | B16: Citric Acid Anhydrous | C16: 0.085019 | D16: =C16*$C$7 -> 0.49542272 | E16: =VLOOKUP($B16,Ingredients!$A:$W,5,FALSE)*$D16/100 -> 1.2236941 | F16: =VLOOKUP($B16,Ingredients!$A:$W,6,FALSE)*$D16/100 -> 0 | G16: =VLOOKUP($B16,Ingredients!$A:$W,7,FALSE)*$D16/100 -> 0 | H16: =VLOOKUP($B16,Ingredients!$A:$W,8,FALSE)*$D16/100 -> 0 | I16: =VLOOKUP($B16,Ingredients!$A:$W,9,FALSE)*$D16/100 -> 0 | J16: =VLOOKUP($B16,Ingredients!$A:$W,10,FALSE)*$D16/100 -> 0 | K16: =VLOOKUP($B16,Ingredients!$A:$W,11,FALSE)*$D16/100 -> 0.49269789 | L16: =VLOOKUP($B16,Ingredients!$A:$W,12,FALSE)*$D16/100 -> 0 | M16: =VLOOKUP($B16,Ingredients!$A:$W,13,FALSE)*$D16/100 -> 0 | N16: =VLOOKUP($B16,Ingredients!$A:$W,14,FALSE)*$D16/100 -> 0 | O16: =VLOOKUP($B16,Ingredients!$A:$W,15,FALSE)*$D16/100 -> 0 | P16: =VLOOKUP($B16,Ingredients!$A:$W,16,FALSE)*$D16/100 -> 0 | Q16: =VLOOKUP($B16,Ingredients!$A:$W,17,FALSE)*$D16/100 -> 0.0014862682 | R16: =VLOOKUP($B16,Ingredients!$A:$W,18,FALSE)*$D16/100 -> 0.0014862682 | S16: =VLOOKUP($B16,Ingredients!$A:$W,19,FALSE)*$D16/100 -> 0.00099084543 | T16: =VLOOKUP($B16,Ingredients!$A:$W,20,FALSE)*$D16/100 -> 0 | U16: =VLOOKUP($B16,Ingredients!$A:$W,21,FALSE)*$D16/100 -> 0 | V16: =VLOOKUP($B16,Ingredients!$A:$W,22,FALSE)*$D16/100 -> 0 | W16: =VLOOKUP($B16,Ingredients!$A:$W,23,FALSE)*$D16/100 -> 0
A17: 4 | B17: Stevia | C17: 0.007428 | D17: =C17*$C$7 -> 0.043284442 | E17: =VLOOKUP($B17,Ingredients!$A:$W,5,FALSE)*$D17/100 -> 0 | F17: =VLOOKUP($B17,Ingredients!$A:$W,6,FALSE)*$D17/100 -> 0 | G17: =VLOOKUP($B17,Ingredients!$A:$W,7,FALSE)*$D17/100 -> 0 | H17: =VLOOKUP($B17,Ingredients!$A:$W,8,FALSE)*$D17/100 -> 0 | I17: =VLOOKUP($B17,Ingredients!$A:$W,9,FALSE)*$D17/100 -> 0 | J17: =VLOOKUP($B17,Ingredients!$A:$W,10,FALSE)*$D17/100 -> 0 | K17: =VLOOKUP($B17,Ingredients!$A:$W,11,FALSE)*$D17/100 -> 0 | L17: =VLOOKUP($B17,Ingredients!$A:$W,12,FALSE)*$D17/100 -> 0 | M17: =VLOOKUP($B17,Ingredients!$A:$W,13,FALSE)*$D17/100 -> 0 | N17: =VLOOKUP($B17,Ingredients!$A:$W,14,FALSE)*$D17/100 -> 0 | O17: =VLOOKUP($B17,Ingredients!$A:$W,15,FALSE)*$D17/100 -> 0 | P17: =VLOOKUP($B17,Ingredients!$A:$W,16,FALSE)*$D17/100 -> 0.00069255107 | Q17: =VLOOKUP($B17,Ingredients!$A:$W,17,FALSE)*$D17/100 -> 0.0017313777 | R17: =VLOOKUP($B17,Ingredients!$A:$W,18,FALSE)*$D17/100 -> 0.0064926662 | S17: =VLOOKUP($B17,Ingredients!$A:$W,19,FALSE)*$D17/100 -> 0 | T17: =VLOOKUP($B17,Ingredients!$A:$W,20,FALSE)*$D17/100 -> 0 | U17: =VLOOKUP($B17,Ingredients!$A:$W,21,FALSE)*$D17/100 -> 0 | V17: =VLOOKUP($B17,Ingredients!$A:$W,22,FALSE)*$D17/100 -> 0 | W17: =VLOOKUP($B17,Ingredients!$A:$W,23,FALSE)*$D17/100 -> 0
A18: 5 | B18: NEW Natural Orange Flavor | C18: 0.023207 | D18: =C18*$C$7 -> 0.13523183 | E18: =VLOOKUP($B18,Ingredients!$A:$W,5,FALSE)*$D18/100 -> 0.51388096 | F18: =VLOOKUP($B18,Ingredients!$A:$W,6,FALSE)*$D18/100 -> 0 | G18: =VLOOKUP($B18,Ingredients!$A:$W,7,FALSE)*$D18/100 -> 0 | H18: =VLOOKUP($B18,Ingredients!$A:$W,8,FALSE)*$D18/100 -> 0 | I18: =VLOOKUP($B18,Ingredients!$A:$W,9,FALSE)*$D18/100 -> 0 | J18: =VLOOKUP($B18,Ingredients!$A:$W,10,FALSE)*$D18/100 -> 0 | K18: =VLOOKUP($B18,Ingredients!$A:$W,11,FALSE)*$D18/100 -> 0.12982256 | L18: =VLOOKUP($B18,Ingredients!$A:$W,12,FALSE)*$D18/100 -> 0 | M18: =VLOOKUP($B18,Ingredients!$A:$W,13,FALSE)*$D18/100 -> 0 | N18: =VLOOKUP($B18,Ingredients!$A:$W,14,FALSE)*$D18/100 -> 0.037864913 | O18: =VLOOKUP($B18,Ingredients!$A:$W,15,FALSE)*$D18/100 -> 0.037864913 | P18: =VLOOKUP($B18,Ingredients!$A:$W,16,FALSE)*$D18/100 -> 0 | Q18: =VLOOKUP($B18,Ingredients!$A:$W,17,FALSE)*$D18/100 -> 0 | R18: =VLOOKUP($B18,Ingredients!$A:$W,18,FALSE)*$D18/100 -> 0.074377507 | S18: =VLOOKUP($B18,Ingredients!$A:$W,19,FALSE)*$D18/100 -> 0.013523183 | T18: =VLOOKUP($B18,Ingredients!$A:$W,20,FALSE)*$D18/100 -> 0 | U18: =VLOOKUP($B18,Ingredients!$A:$W,21,FALSE)*$D18/100 -> 0 | V18: =VLOOKUP($B18,Ingredients!$A:$W,22,FALSE)*$D18/100 -> 0 | W18: =VLOOKUP($B18,Ingredients!$A:$W,23,FALSE)*$D18/100 -> 0
A19: 6 | B19: Paprika | C19: 0.003516 | D19: =C19*$C$7 -> 0.020488435 | E19: =VLOOKUP($B19,Ingredients!$A:$W,5,FALSE)*$D19/100 -> 0.10136858 | F19: =VLOOKUP($B19,Ingredients!$A:$W,6,FALSE)*$D19/100 -> 0.039460726 | G19: =VLOOKUP($B19,Ingredients!$A:$W,7,FALSE)*$D19/100 -> 0.0043845251 | H19: =VLOOKUP($B19,Ingredients!$A:$W,8,FALSE)*$D19/100 -> 0.00077651169 | I19: =VLOOKUP($B19,Ingredients!$A:$W,9,FALSE)*$D19/100 -> 0 | J19: =VLOOKUP($B19,Ingredients!$A:$W,10,FALSE)*$D19/100 -> 0 | K19: =VLOOKUP($B19,Ingredients!$A:$W,11,FALSE)*$D19/100 -> 0.015429841 | L19: =VLOOKUP($B19,Ingredients!$A:$W,12,FALSE)*$D19/100 -> 0 | M19: =VLOOKUP($B19,Ingredients!$A:$W,13,FALSE)*$D19/100 -> 0 | N19: =VLOOKUP($B19,Ingredients!$A:$W,14,FALSE)*$D19/100 -> 0.0065665435 | O19: =VLOOKUP($B19,Ingredients!$A:$W,15,FALSE)*$D19/100 -> 0.0065665435 | P19: =VLOOKUP($B19,Ingredients!$A:$W,16,FALSE)*$D19/100 -> 0 | Q19: =VLOOKUP($B19,Ingredients!$A:$W,17,FALSE)*$D19/100 -> 0.00056343197 | R19: =VLOOKUP($B19,Ingredients!$A:$W,18,FALSE)*$D19/100 -> 3.6879183e-05 | S19: =VLOOKUP($B19,Ingredients!$A:$W,19,FALSE)*$D19/100 -> 0 | T19: =VLOOKUP($B19,Ingredients!$A:$W,20,FALSE)*$D19/100 -> 0.38088821 | U19: =VLOOKUP($B19,Ingredients!$A:$W,21,FALSE)*$D19/100 -> 0.0001270283 | V19: =VLOOKUP($B19,Ingredients!$A:$W,22,FALSE)*$D19/100 -> 0 | W19: =VLOOKUP($B19,Ingredients!$A:$W,23,FALSE)*$D19/100 -> 0
A20: 7 | B20: Turmeric | C20: 0.001319 | D20: =C20*$C$7 -> 0.0076860768 | E20: =VLOOKUP($B20,Ingredients!$A:$W,5,FALSE)*$D20/100 -> 0.024647711 | F20: =VLOOKUP($B20,Ingredients!$A:$W,6,FALSE)*$D20/100 -> 2.7669876e-05 | G20: =VLOOKUP($B20,Ingredients!$A:$W,7,FALSE)*$D20/100 -> 3.0744307e-06 | H20: =VLOOKUP($B20,Ingredients!$A:$W,8,FALSE)*$D20/100 -> 1.5372154e-06 | I20: =VLOOKUP($B20,Ingredients!$A:$W,9,FALSE)*$D20/100 -> 0 | J20: =VLOOKUP($B20,Ingredients!$A:$W,10,FALSE)*$D20/100 -> 0 | K20: =VLOOKUP($B20,Ingredients!$A:$W,11,FALSE)*$D20/100 -> 0.0061465556 | L20: =VLOOKUP($B20,Ingredients!$A:$W,12,FALSE)*$D20/100 -> 0 | M20: =VLOOKUP($B20,Ingredients!$A:$W,13,FALSE)*$D20/100 -> 0 | N20: =VLOOKUP($B20,Ingredients!$A:$W,14,FALSE)*$D20/100 -> 0.0013104761 | O20: =VLOOKUP($B20,Ingredients!$A:$W,15,FALSE)*$D20/100 -> 0.0013104761 | P20: =VLOOKUP($B20,Ingredients!$A:$W,16,FALSE)*$D20/100 -> 6.9174691e-06 | Q20: =VLOOKUP($B20,Ingredients!$A:$W,17,FALSE)*$D20/100 -> 0.0022404914 | R20: =VLOOKUP($B20,Ingredients!$A:$W,18,FALSE)*$D20/100 -> 0.0061434812 | S20: =VLOOKUP($B20,Ingredients!$A:$W,19,FALSE)*$D20/100 -> 0.00061796057 | T20: =VLOOKUP($B20,Ingredients!$A:$W,20,FALSE)*$D20/100 -> 0 | U20: =VLOOKUP($B20,Ingredients!$A:$W,21,FALSE)*$D20/100 -> 0 | V20: =VLOOKUP($B20,Ingredients!$A:$W,22,FALSE)*$D20/100 -> 0 | W20: =VLOOKUP($B20,Ingredients!$A:$W,23,FALSE)*$D20/100 -> 0
A21: 8
A22: 9
A23: 10
A24: 11
A25: 12
A26: 13
A27: 14
A28: 15
A29: 16
A30: 17
A31: 18
A32: 19
... A34: 21

Sheet Nutrition STONF
A1: edit yellow/orange cells | C1: NOTE: RULES COPIED FROM THIS TAB!!!!
A2: Formulation | B2: STONF | D2: =A2&" "& B2 -> Formulation STONF | G2: {=INDIRECT("'"&D2&"'!C7")} -> 5.8272 | H2: grams | I2: single dose
A3: ='Formulation STOF2'!B6 -> Smooth Texture Sugar Free Orange Natural Dyes | D3: 1g =0.00220462lb | E3: 1g =0.035274oz | G3: {=INDIRECT("'"&D2&"'!D6")} -> 11.6544 | H3: grams | I3: double dose
A5: Calorie Rules | B5: B | C5: =(4*F24)+(4*C10)+(9*C31) -> 21.58066 | D5: Calories | E5: Per 21 CFR 101.9 (c) (1) (i): part (B) | F5: Total Calories [Per 21 CFR 101.9 (c) (1) (i): part (B) – not using Total Fiber value] = (4 x Protein) + (4 x Total Carbohydrate) + (9 x Total Fat)
B6: C | C6: =(4*F24)+(9*C31)+(4*(C10-D10))+(2*D10) -> 16.112245 | D6: Calories | E6: Per 21 CFR 101.9 (c) (1) (i): part (C) | F6: Total Calories [Per 21 CFR 101.9 (c) (1) (i): part (C) – do NOT have Soluble/Insoluble Fiber values, only Total Fiber] = (4 x Protein) + (9 x Total Fat) + [4 x (Total Carbohydrate – Total Fiber)] + [2 x Total Fiber]
B7: C+ | C7: =(4*F24)+(9*C31)+(4*(C10-D10))+(2*E10) -> 15.244346 | D7: Calories | E7: Per 21 CFR 101.9 (c) (1) (i): part (C) | F7: Total Calories [Per 21 CFR 101.9 (c) (1) (i): part (C) – have Soluble/Insoluble Fiber values] = (4 x Protein) + (9 x Total Fat) + [4 x (Total Carbohydrate – Total Fiber)] + [2 x Soluble Fiber]
A9: Class II - NLT 80% of Label | C9: {=INDIRECT("'"&D2&"'!K13")} -> Total carbohydrate | D9: {=INDIRECT("'"&D2&"'!L13")} -> Total dietary fiber | E9: {=INDIRECT("'"&D2&"'!M13")} -> Soluble fiber
B10: Totals | C10: {=INDIRECT("'"&D2&"'!K8")} -> 5.2370083 | D10: {=INDIRECT("'"&D2&"'!L8")} -> 2.7342075 | E10: {=INDIRECT("'"&D2&"'!M8")} -> 2.3002581
B11: RDI | C11: 275 | D11: 28 | E11: NA
B12: %RDI | C12: =C10/C11 -> 0.019043667 | D12: =D10/D11 -> 0.097650269 | E12: NA
C13: < 0.5g - express as 0 < 1g - express as "contains less than 1g" or "less than 1g" ≥1g - express to nearest 1g increment Insignificant amount is < 1g | D13: < 0.5g - express as 0 < 1g - express as "contains less than 1g" or "less than 1g" ≥1g - express to nearest 1g increment Insignificant amount is < 1g | E13: - Label value based on calculation of psyllium being 70% soluble fiber (3.4g psyllium * 0.70 = 2.4g) < 0.5g - express as 0 < 1g - express as "contains less than 1g" or "less than 1g" ≥1g - express to nearest 1g increment Insignificant amount is < 0.5g
B14: Reco. | C14: 5g | D14: 3g | E14: 2g
A16: Class II - NLT 80% of Label | C16: Iron [Mandatory] | D16: Potassium [Mandatory] | E16: Calcium [Mandatory]
B17: Totals | C17: {=INDIRECT("'"&D2&"'!P8")} -> 0.26450766 | D17: {=INDIRECT("'"&D2&"'!Q8")} -> 27.641747 | E17: {=INDIRECT("'"&D2&"'!S8")} -> 5.9167702
B18: RDI | C18: 18 | D18: 4700 | E18: 1300
B19: %RDI | C19: =C17/C18 -> 0.01469487 | D19: =D17/D18 -> 0.0058812227 | E19: =E17/E18 -> 0.0045513617
C20: <2% DV: shall not be declared > 2% DV: round to nearest 0.1 mg and round to nearest % DV | D20: <2% DV: shall not be declared > 2% DV: round to nearest 10 mg and round to nearest % DV | E20: <2% DV: shall not be declared > 2% DV: round to nearest 10 mg and round to nearest % DV
B21: Reco. | C21: 2% DV | D21: 30 mg | E21: 0
A23: Class II - NLT 80% of Label | C23: Vitamin A [Voluntary] | D23: Vitamin C [Voluntary] | E23: Vitamin D [Mandatory] | F23: Protein
B24: Totals | C24: {=INDIRECT("'"&D2&"'!T8")} -> 0.38088821 | D24: {=INDIRECT("'"&D2&"'!U8")} -> 0.0001270283 | E24: {=INDIRECT("'"&D2&"'!V8")} -> 0 | F24: {=INDIRECT("'"&D2&"'!W8")} -> 0.074137882
B25: RDI | C25: 900 mcg RAE | D25: 90 | E25: 20 microgram | F25: NA
B26: %RDI | C26: NA | D26: NA | E26: =E24/20 -> 0 | F26: NA
C27: <2% DV: shall not be declared > 2% DV: round to nearest 10 mcg RAE and round to nearest % DV | D27: <2% DV: shall not be declared > 2% DV: round to nearest 1 mg and round to nearest % DV | E27: <2% DV: shall not be declared > 2% DV: round to nearest 0.1 mcg and round to nearest % DV | F27: < 0.5g - express as 0 < 1g - express as "contains less than 1g" or "less than 1g" ≥1g - express to nearest 1g increment Insignificant amount is < 0.5g
B28: Reco. | C28: none | D28: none | E28: 0 | F28: 0g
A30: Third Group - NMT 120% of Label | C30: Total Fat | D30: Saturated Fat | E30: Trans Fat | F30: Cholesterol
B31: Totals | C31: {=INDIRECT("'"&D2&"'!G8")} -> 0.037341652 | D31: {=INDIRECT("'"&D2&"'!H8")} -> 0.0061942595 | E31: {=INDIRECT("'"&D2&"'!I8")} -> 0 | F31: {=INDIRECT("'"&D2&"'!J8")} -> 0
B32: RDI | C32: 78 | D32: 20 | E32: NA | F32: 300 mg
B33: %RDI | C33: NA | D33: NA | E33: NA | F33: NA
C34: < 0.5g - express as 0 < 5 g - nearest 0.5 g increment > 5 g: nearest 1 g increment | D34: < 0.5g - express as 0 < 5 g - nearest 0.5 g increment > 5 g: nearest 1 g increment | E34: < 0.5g - express as 0 < 5 g - nearest 0.5 g increment > 5 g: nearest 1 g increment | F34: < 2mg: express as 0 2-5 mg: "less than 5 mg" > 5 mg: 5 mg increment
B35: Reco. | C35: none | D35: none | E35: none | F35: none
A37: Third Group - NMT 120% of Label | C37: {=INDIRECT("'"&D2&"'!E13")} -> Calories (US Rules) | D37: Calories from Fat | E37: {=INDIRECT("'"&D2&"'!N13")} -> Sugar | F37: {=INDIRECT("'"&D2&"'!O13")} -> Added Sugars | G37: {=INDIRECT("'"&D2&"'!R13")} -> Sodium
B38: Totals | C38: =C7 -> 15.244346 | D38: {=INDIRECT("'"&D2&"'!F8")} -> 0.18050564 | E38: {=INDIRECT("'"&D2&"'!N8")} -> 0.11418553 | F38: {=INDIRECT("'"&D2&"'!O8")} -> 0.045741932 | G38: {=INDIRECT("'"&D2&"'!R8")} -> 5.1773643
C39: NA | D39: NA | E39: NA | F39: 50 | G39: 2300
B40: %RDI | C40: NA | D40: NA | E40: NA | F40: =F38/F39 -> 0.00091483864 | G40: =G38/G39 -> 0.002251028
C41: < 5 cal - express as 0 ≤ 50 cal - express to nearest 5 cal increment > 50 cal - express to nearest 10 cal increment Insignificant amount is < 5 cal | D41: Not required to be declared | E41: < 0.5g - express as 0 < 1g - express as "contains less than 1g" or "less than 1g" ≥1g - express to nearest 1g increment Insignificant amount is < 0.5g | F41: < 0.5g - express as 0 < 1g - express as "contains less than 1g" or "less than 1g" ≥1g - express to nearest 1g increment Insignificant amount is < 0.5g | G41: < 5mg - express as 0 5-140mg - express to nearest 5mg increment > 140mg - express to nearest 10mg increment Insignificant amount is < 5mg
B42: Reco. | C42: 15kCal | D42: none | E42: 0 | F42: 0 | G42: 5mg

Sheet Formulation STONF2
B1: Edited/created on | C1: 46078 | D1: By | E1: Brooke Baker | F1: for | G1: Project 5-way
B2: Pick list items in blue
B3: edit yellow/orange cells
B4: green are results
B5: Product | C5: GCAS | D5: STONF2
B6: Smooth Texture Sugar Free Orange Natural Dyes | C6: 5.8272 | D6: =C6*2 -> 11.6544
B7: DRIVER (g weight) | C7: =C6 -> 5.8272 | E7: US rules (C) with sol. Fiber
B8: Total = | C8: =SUM(C14:C34) -> 1 | D8: =SUM(D14:D21) -> 5.8272 | E8: ='Nutrition STOF'!C7 -> 30.349742 | F8: =SUM(F14:F34) -> 0.18050564 | G8: =SUM(G14:G34) -> 0.037341652 | H8: =SUM(H14:H34) -> 0.0061942595 | I8: =SUM(I14:I34) -> 0 | J8: =SUM(J14:J34) -> 0 | K8: =SUM(K14:K34) -> 5.2370083 | L8: =SUM(L14:L34) -> 2.7342075 | M8: =SUM(M14:M34) -> 2.3002581 | ... W8: =SUM(W14:W34) -> 0.074137882
E9: add g, mg, IU, ncg / 100 g row
B10: servings | C10: 2 | D10: =C6*2 -> 11.6544 | E10: =E8*$C$10 -> 60.699483 | F10: =F8*$C$10 -> 0.36101128 | G10: =G8*$C$10 -> 0.074683304 | H10: =H8*$C$10 -> 0.012388519 | I10: =I8*$C$10 -> 0 | J10: =J8*$C$10 -> 0 | K10: =K8*$C$10 -> 10.474017 | L10: =L8*$C$10 -> 5.4684151 | ... W10: =W8*$C$10 -> 0.14827576
C12: =SUM(C14:C34) -> 1
B13: Ingredient | C13: % w/w | D13: Dose wt | E13: Calories (US Rules) | F13: Calories from Fat | G13: Total Fat | H13: Saturated Fat | I13: Trans Fat | J13: Cholesterol | K13: Total carbohydrate | L13: Total dietary fiber | M13: Soluble fiber | N13: Sugar | O13: Added Sugars | P13: Iron | Q13: Potassium | R13: Sodium | S13: Calcium | T13: Vitamin A | U13: Vitamin C | V13: Vitamin D | W13: Protein
A14: 1 | B14: Psyllium | C14: 0.559922 | D14: =C14*$C$7 -> 3.2627775 | E14: =VLOOKUP($B14,Ingredients!$A:$W,5,FALSE)*$D14/100 -> 11.772101 | F14: =VLOOKUP($B14,Ingredients!$A:$W,6,FALSE)*$D14/100 -> 0.14101724 | G14: =VLOOKUP($B14,Ingredients!$A:$W,7,FALSE)*$D14/100 -> 0.032954053 | H14: =VLOOKUP($B14,Ingredients!$A:$W,8,FALSE)*$D14/100 -> 0.0054162106 | I14: =VLOOKUP($B14,Ingredients!$A:$W,9,FALSE)*$D14/100 -> 0 | J14: =VLOOKUP($B14,Ingredients!$A:$W,10,FALSE)*$D14/100 -> 0 | K14: =VLOOKUP($B14,Ingredients!$A:$W,11,FALSE)*$D14/100 -> 2.8386164 | L14: =VLOOKUP($B14,Ingredients!$A:$W,12,FALSE)*$D14/100 -> 2.7342075 | M14: =VLOOKUP($B14,Ingredients!$A:$W,13,FALSE)*$D14/100 -> 2.3002581 | N14: =VLOOKUP($B14,Ingredients!$A:$W,14,FALSE)*$D14/100 -> 0.0032627775 | O14: =VLOOKUP($B14,Ingredients!$A:$W,15,FALSE)*$D14/100 -> 0 | P14: =VLOOKUP($B14,Ingredients!$A:$W,16,FALSE)*$D14/100 -> 0.25449664 | Q14: =VLOOKUP($B14,Ingredients!$A:$W,17,FALSE)*$D14/100 -> 27.635725 | R14: =VLOOKUP($B14,Ingredients!$A:$W,18,FALSE)*$D14/100 -> 2.295364 | S14: =VLOOKUP($B14,Ingredients!$A:$W,19,FALSE)*$D14/100 -> 5.7154073 | T14: =VLOOKUP($B14,Ingredients!$A:$W,20,FALSE)*$D14/100 -> 0 | U14: =VLOOKUP($B14,Ingredients!$A:$W,21,FALSE)*$D14/100 -> 0 | V14: =VLOOKUP($B14,Ingredients!$A:$W,22,FALSE)*$D14/100 -> 0 | W14: =VLOOKUP($B14,Ingredients!$A:$W,23,FALSE)*$D14/100 -> 0.068550955
A15: 2 | B15: Maltodextrin | C15: 0.319589 | D15: =C15*$C$7 -> 1.862309 | E15: =VLOOKUP($B15,Ingredients!$A:$W,5,FALSE)*$D15/100 -> 7.0395281 | F15: =VLOOKUP($B15,Ingredients!$A:$W,6,FALSE)*$D15/100 -> 0 | G15: =VLOOKUP($B15,Ingredients!$A:$W,7,FALSE)*$D15/100 -> 0 | H15: =VLOOKUP($B15,Ingredients!$A:$W,8,FALSE)*$D15/100 -> 0 | I15: =VLOOKUP($B15,Ingredients!$A:$W,9,FALSE)*$D15/100 -> 0 | J15: =VLOOKUP($B15,Ingredients!$A:$W,10,FALSE)*$D15/100 -> 0 | K15: =VLOOKUP($B15,Ingredients!$A:$W,11,FALSE)*$D15/100 -> 1.7542951 | L15: =VLOOKUP($B15,Ingredients!$A:$W,12,FALSE)*$D15/100 -> 0 | M15: =VLOOKUP($B15,Ingredients!$A:$W,13,FALSE)*$D15/100 -> 0 | N15: =VLOOKUP($B15,Ingredients!$A:$W,14,FALSE)*$D15/100 -> 0.065180816 | O15: =VLOOKUP($B15,Ingredients!$A:$W,15,FALSE)*$D15/100 -> 0 | P15: =VLOOKUP($B15,Ingredients!$A:$W,16,FALSE)*$D15/100 -> 0.0093115451 | Q15: =VLOOKUP($B15,Ingredients!$A:$W,17,FALSE)*$D15/100 -> 0 | R15: =VLOOKUP($B15,Ingredients!$A:$W,18,FALSE)*$D15/100 -> 2.7934635 | S15: =VLOOKUP($B15,Ingredients!$A:$W,19,FALSE)*$D15/100 -> 0.1862309 | T15: =VLOOKUP($B15,Ingredients!$A:$W,20,FALSE)*$D15/100 -> 0 | U15: =VLOOKUP($B15,Ingredients!$A:$W,21,FALSE)*$D15/100 -> 0 | V15: =VLOOKUP($B15,Ingredients!$A:$W,22,FALSE)*$D15/100 -> 0 | W15: =VLOOKUP($B15,Ingredients!$A:$W,23,FALSE)*$D15/100 -> 0.0055869271
A16: 3 | B16: Citric Acid Anhydrous | C16: 0.085019 | D16: =C16*$C$7 -> 0.49542272 | E16: =VLOOKUP($B16,Ingredients!$A:$W,5,FALSE)*$D16/100 -> 1.2236941 | F16: =VLOOKUP($B16,Ingredients!$A:$W,6,FALSE)*$D16/100 -> 0 | G16: =VLOOKUP($B16,Ingredients!$A:$W,7,FALSE)*$D16/100 -> 0 | H16: =VLOOKUP($B16,Ingredients!$A:$W,8,FALSE)*$D16/100 -> 0 | I16: =VLOOKUP($B16,Ingredients!$A:$W,9,FALSE)*$D16/100 -> 0 | J16: =VLOOKUP($B16,Ingredients!$A:$W,10,FALSE)*$D16/100 -> 0 | K16: =VLOOKUP($B16,Ingredients!$A:$W,11,FALSE)*$D16/100 -> 0.49269789 | L16: =VLOOKUP($B16,Ingredients!$A:$W,12,FALSE)*$D16/100 -> 0 | M16: =VLOOKUP($B16,Ingredients!$A:$W,13,FALSE)*$D16/100 -> 0 | N16: =VLOOKUP($B16,Ingredients!$A:$W,14,FALSE)*$D16/100 -> 0 | O16: =VLOOKUP($B16,Ingredients!$A:$W,15,FALSE)*$D16/100 -> 0 | P16: =VLOOKUP($B16,Ingredients!$A:$W,16,FALSE)*$D16/100 -> 0 | Q16: =VLOOKUP($B16,Ingredients!$A:$W,17,FALSE)*$D16/100 -> 0.0014862682 | R16: =VLOOKUP($B16,Ingredients!$A:$W,18,FALSE)*$D16/100 -> 0.0014862682 | S16: =VLOOKUP($B16,Ingredients!$A:$W,19,FALSE)*$D16/100 -> 0.00099084543 | T16: =VLOOKUP($B16,Ingredients!$A:$W,20,FALSE)*$D16/100 -> 0 | U16: =VLOOKUP($B16,Ingredients!$A:$W,21,FALSE)*$D16/100 -> 0 | V16: =VLOOKUP($B16,Ingredients!$A:$W,22,FALSE)*$D16/100 -> 0 | W16: =VLOOKUP($B16,Ingredients!$A:$W,23,FALSE)*$D16/100 -> 0
A17: 4 | B17: Stevia | C17: 0.007428 | D17: =C17*$C$7 -> 0.043284442 | E17: =VLOOKUP($B17,Ingredients!$A:$W,5,FALSE)*$D17/100 -> 0 | F17: =VLOOKUP($B17,Ingredients!$A:$W,6,FALSE)*$D17/100 -> 0 | G17: =VLOOKUP($B17,Ingredients!$A:$W,7,FALSE)*$D17/100 -> 0 | H17: =VLOOKUP($B17,Ingredients!$A:$W,8,FALSE)*$D17/100 -> 0 | I17: =VLOOKUP($B17,Ingredients!$A:$W,9,FALSE)*$D17/100 -> 0 | J17: =VLOOKUP($B17,Ingredients!$A:$W,10,FALSE)*$D17/100 -> 0 | K17: =VLOOKUP($B17,Ingredients!$A:$W,11,FALSE)*$D17/100 -> 0 | L17: =VLOOKUP($B17,Ingredients!$A:$W,12,FALSE)*$D17/100 -> 0 | M17: =VLOOKUP($B17,Ingredients!$A:$W,13,FALSE)*$D17/100 -> 0 | N17: =VLOOKUP($B17,Ingredients!$A:$W,14,FALSE)*$D17/100 -> 0 | O17: =VLOOKUP($B17,Ingredients!$A:$W,15,FALSE)*$D17/100 -> 0 | P17: =VLOOKUP($B17,Ingredients!$A:$W,16,FALSE)*$D17/100 -> 0.00069255107 | Q17: =VLOOKUP($B17,Ingredients!$A:$W,17,FALSE)*$D17/100 -> 0.0017313777 | R17: =VLOOKUP($B17,Ingredients!$A:$W,18,FALSE)*$D17/100 -> 0.0064926662 | S17: =VLOOKUP($B17,Ingredients!$A:$W,19,FALSE)*$D17/100 -> 0 | T17: =VLOOKUP($B17,Ingredients!$A:$W,20,FALSE)*$D17/100 -> 0 | U17: =VLOOKUP($B17,Ingredients!$A:$W,21,FALSE)*$D17/100 -> 0 | V17: =VLOOKUP($B17,Ingredients!$A:$W,22,FALSE)*$D17/100 -> 0 | W17: =VLOOKUP($B17,Ingredients!$A:$W,23,FALSE)*$D17/100 -> 0
A18: 5 | B18: NEW Natural Orange Flavor | C18: 0.023207 | D18: =C18*$C$7 -> 0.13523183 | E18: =VLOOKUP($B18,Ingredients!$A:$W,5,FALSE)*$D18/100 -> 0.51388096 | F18: =VLOOKUP($B18,Ingredients!$A:$W,6,FALSE)*$D18/100 -> 0 | G18: =VLOOKUP($B18,Ingredients!$A:$W,7,FALSE)*$D18/100 -> 0 | H18: =VLOOKUP($B18,Ingredients!$A:$W,8,FALSE)*$D18/100 -> 0 | I18: =VLOOKUP($B18,Ingredients!$A:$W,9,FALSE)*$D18/100 -> 0 | J18: =VLOOKUP($B18,Ingredients!$A:$W,10,FALSE)*$D18/100 -> 0 | K18: =VLOOKUP($B18,Ingredients!$A:$W,11,FALSE)*$D18/100 -> 0.12982256 | L18: =VLOOKUP($B18,Ingredients!$A:$W,12,FALSE)*$D18/100 -> 0 | M18: =VLOOKUP($B18,Ingredients!$A:$W,13,FALSE)*$D18/100 -> 0 | N18: =VLOOKUP($B18,Ingredients!$A:$W,14,FALSE)*$D18/100 -> 0.037864913 | O18: =VLOOKUP($B18,Ingredients!$A:$W,15,FALSE)*$D18/100 -> 0.037864913 | P18: =VLOOKUP($B18,Ingredients!$A:$W,16,FALSE)*$D18/100 -> 0 | Q18: =VLOOKUP($B18,Ingredients!$A:$W,17,FALSE)*$D18/100 -> 0 | R18: =VLOOKUP($B18,Ingredients!$A:$W,18,FALSE)*$D18/100 -> 0.074377507 | S18: =VLOOKUP($B18,Ingredients!$A:$W,19,FALSE)*$D18/100 -> 0.013523183 | T18: =VLOOKUP($B18,Ingredients!$A:$W,20,FALSE)*$D18/100 -> 0 | U18: =VLOOKUP($B18,Ingredients!$A:$W,21,FALSE)*$D18/100 -> 0 | V18: =VLOOKUP($B18,Ingredients!$A:$W,22,FALSE)*$D18/100 -> 0 | W18: =VLOOKUP($B18,Ingredients!$A:$W,23,FALSE)*$D18/100 -> 0
A19: 6 | B19: Paprika | C19: 0.003516 | D19: =C19*$C$7 -> 0.020488435 | E19: =VLOOKUP($B19,Ingredients!$A:$W,5,FALSE)*$D19/100 -> 0.10136858 | F19: =VLOOKUP($B19,Ingredients!$A:$W,6,FALSE)*$D19/100 -> 0.039460726 | G19: =VLOOKUP($B19,Ingredients!$A:$W,7,FALSE)*$D19/100 -> 0.0043845251 | H19: =VLOOKUP($B19,Ingredients!$A:$W,8,FALSE)*$D19/100 -> 0.00077651169 | I19: =VLOOKUP($B19,Ingredients!$A:$W,9,FALSE)*$D19/100 -> 0 | J19: =VLOOKUP($B19,Ingredients!$A:$W,10,FALSE)*$D19/100 -> 0 | K19: =VLOOKUP($B19,Ingredients!$A:$W,11,FALSE)*$D19/100 -> 0.015429841 | L19: =VLOOKUP($B19,Ingredients!$A:$W,12,FALSE)*$D19/100 -> 0 | M19: =VLOOKUP($B19,Ingredients!$A:$W,13,FALSE)*$D19/100 -> 0 | N19: =VLOOKUP($B19,Ingredients!$A:$W,14,FALSE)*$D19/100 -> 0.0065665435 | O19: =VLOOKUP($B19,Ingredients!$A:$W,15,FALSE)*$D19/100 -> 0.0065665435 | P19: =VLOOKUP($B19,Ingredients!$A:$W,16,FALSE)*$D19/100 -> 0 | Q19: =VLOOKUP($B19,Ingredients!$A:$W,17,FALSE)*$D19/100 -> 0.00056343197 | R19: =VLOOKUP($B19,Ingredients!$A:$W,18,FALSE)*$D19/100 -> 3.6879183e-05 | S19: =VLOOKUP($B19,Ingredients!$A:$W,19,FALSE)*$D19/100 -> 0 | T19: =VLOOKUP($B19,Ingredients!$A:$W,20,FALSE)*$D19/100 -> 0.38088821 | U19: =VLOOKUP($B19,Ingredients!$A:$W,21,FALSE)*$D19/100 -> 0.0001270283 | V19: =VLOOKUP($B19,Ingredients!$A:$W,22,FALSE)*$D19/100 -> 0 | W19: =VLOOKUP($B19,Ingredients!$A:$W,23,FALSE)*$D19/100 -> 0
A20: 7 | B20: Turmeric | C20: 0.001319 | D20: =C20*$C$7 -> 0.0076860768 | E20: =VLOOKUP($B20,Ingredients!$A:$W,5,FALSE)*$D20/100 -> 0.024647711 | F20: =VLOOKUP($B20,Ingredients!$A:$W,6,FALSE)*$D20/100 -> 2.7669876e-05 | G20: =VLOOKUP($B20,Ingredients!$A:$W,7,FALSE)*$D20/100 -> 3.0744307e-06 | H20: =VLOOKUP($B20,Ingredients!$A:$W,8,FALSE)*$D20/100 -> 1.5372154e-06 | I20: =VLOOKUP($B20,Ingredients!$A:$W,9,FALSE)*$D20/100 -> 0 | J20: =VLOOKUP($B20,Ingredients!$A:$W,10,FALSE)*$D20/100 -> 0 | K20: =VLOOKUP($B20,Ingredients!$A:$W,11,FALSE)*$D20/100 -> 0.0061465556 | L20: =VLOOKUP($B20,Ingredients!$A:$W,12,FALSE)*$D20/100 -> 0 | M20: =VLOOKUP($B20,Ingredients!$A:$W,13,FALSE)*$D20/100 -> 0 | N20: =VLOOKUP($B20,Ingredients!$A:$W,14,FALSE)*$D20/100 -> 0.0013104761 | O20: =VLOOKUP($B20,Ingredients!$A:$W,15,FALSE)*$D20/100 -> 0.0013104761 | P20: =VLOOKUP($B20,Ingredients!$A:$W,16,FALSE)*$D20/100 -> 6.9174691e-06 | Q20: =VLOOKUP($B20,Ingredients!$A:$W,17,FALSE)*$D20/100 -> 0.0022404914 | R20: =VLOOKUP($B20,Ingredients!$A:$W,18,FALSE)*$D20/100 -> 0.0061434812 | S20: =VLOOKUP($B20,Ingredients!$A:$W,19,FALSE)*$D20/100 -> 0.00061796057 | T20: =VLOOKUP($B20,Ingredients!$A:$W,20,FALSE)*$D20/100 -> 0 | U20: =VLOOKUP($B20,Ingredients!$A:$W,21,FALSE)*$D20/100 -> 0 | V20: =VLOOKUP($B20,Ingredients!$A:$W,22,FALSE)*$D20/100 -> 0 | W20: =VLOOKUP($B20,Ingredients!$A:$W,23,FALSE)*$D20/100 -> 0
A21: 8
A22: 9
A23: 10
A24: 11
A25: 12
A26: 13
A27: 14
A28: 15
A29: 16
A30: 17
A31: 18
A32: 19
... A34: 21

Sheet Nutrition STONF2
A1: edit yellow/orange cells | C1: NOTE: RULES COPIED FROM THIS TAB!!!!
A2: Formulation | B2: STONF2 | D2: =A2&" "& B2 -> Formulation STONF2 | G2: {=INDIRECT("'"&D2&"'!C7")} -> 5.8272 | H2: grams | I2: single dose
A3: ='Formulation STOF2'!B6 -> Smooth Texture Sugar Free Orange Natural Dyes | D3: 1g =0.00220462lb | E3: 1g =0.035274oz | G3: {=INDIRECT("'"&D2&"'!D6")} -> 11.6544 | H3: grams | I3: double dose
A5: Calorie Rules | B5: B | C5: =(4*F24)+(4*C10)+(9*C31) -> 21.58066 | D5: Calories | E5: Per 21 CFR 101.9 (c) (1) (i): part (B) | F5: Total Calories [Per 21 CFR 101.9 (c) (1) (i): part (B) – not using Total Fiber value] = (4 x Protein) + (4 x Total Carbohydrate) + (9 x Total Fat)
B6: C | C6: =(4*F24)+(9*C31)+(4*(C10-D10))+(2*D10) -> 16.112245 | D6: Calories | E6: Per 21 CFR 101.9 (c) (1) (i): part (C) | F6: Total Calories [Per 21 CFR 101.9 (c) (1) (i): part (C) – do NOT have Soluble/Insoluble Fiber values, only Total Fiber] = (4 x Protein) + (9 x Total Fat) + [4 x (Total Carbohydrate – Total Fiber)] + [2 x Total Fiber]
B7: C+ | C7: =(4*F24)+(9*C31)+(4*(C10-D10))+(2*E10) -> 15.244346 | D7: Calories | E7: Per 21 CFR 101.9 (c) (1) (i): part (C) | F7: Total Calories [Per 21 CFR 101.9 (c) (1) (i): part (C) – have Soluble/Insoluble Fiber values] = (4 x Protein) + (9 x Total Fat) + [4 x (Total Carbohydrate – Total Fiber)] + [2 x Soluble Fiber]
A9: Class II - NLT 80% of Label | C9: {=INDIRECT("'"&D2&"'!K13")} -> Total carbohydrate | D9: {=INDIRECT("'"&D2&"'!L13")} -> Total dietary fiber | E9: {=INDIRECT("'"&D2&"'!M13")} -> Soluble fiber
B10: Totals | C10: {=INDIRECT("'"&D2&"'!K8")} -> 5.2370083 | D10: {=INDIRECT("'"&D2&"'!L8")} -> 2.7342075 | E10: {=INDIRECT("'"&D2&"'!M8")} -> 2.3002581
B11: RDI | C11: 275 | D11: 28 | E11: NA
B12: %RDI | C12: =C10/C11 -> 0.019043667 | D12: =D10/D11 -> 0.097650269 | E12: NA
C13: < 0.5g - express as 0 < 1g - express as "contains less than 1g" or "less than 1g" ≥1g - express to nearest 1g increment Insignificant amount is < 1g | D13: < 0.5g - express as 0 < 1g - express as "contains less than 1g" or "less than 1g" ≥1g - express to nearest 1g increment Insignificant amount is < 1g | E13: - Label value based on calculation of psyllium being 70% soluble fiber (3.4g psyllium * 0.70 = 2.4g) < 0.5g - express as 0 < 1g - express as "contains less than 1g" or "less than 1g" ≥1g - express to nearest 1g increment Insignificant amount is < 0.5g
B14: Reco. | C14: 5g | D14: 3g | E14: 2g
A16: Class II - NLT 80% of Label | C16: Iron [Mandatory] | D16: Potassium [Mandatory] | E16: Calcium [Mandatory]
B17: Totals | C17: {=INDIRECT("'"&D2&"'!P8")} -> 0.26450766 | D17: {=INDIRECT("'"&D2&"'!Q8")} -> 27.641747 | E17: {=INDIRECT("'"&D2&"'!S8")} -> 5.9167702
B18: RDI | C18: 18 | D18: 4700 | E18: 1300
B19: %RDI | C19: =C17/C18 -> 0.01469487 | D19: =D17/D18 -> 0.0058812227 | E19: =E17/E18 -> 0.0045513617
C20: <2% DV: shall not be declared > 2% DV: round to nearest 0.1 mg and round to nearest % DV | D20: <2% DV: shall not be declared > 2% DV: round to nearest 10 mg and round to nearest % DV | E20: <2% DV: shall not be declared > 2% DV: round to nearest 10 mg and round to nearest % DV
B21: Reco. | C21: 2% DV | D21: 30 mg | E21: 0
A23: Class II - NLT 80% of Label | C23: Vitamin A [Voluntary] | D23: Vitamin C [Voluntary] | E23: Vitamin D [Mandatory] | F23: Protein
B24: Totals | C24: {=INDIRECT("'"&D2&"'!T8")} -> 0.38088821 | D24: {=INDIRECT("'"&D2&"'!U8")} -> 0.0001270283 | E24: {=INDIRECT("'"&D2&"'!V8")} -> 0 | F24: {=INDIRECT("'"&D2&"'!W8")} -> 0.074137882
B25: RDI | C25: 900 mcg RAE | D25: 90 | E25: 20 microgram | F25: NA
B26: %RDI | C26: NA | D26: NA | E26: =E24/20 -> 0 | F26: NA
C27: <2% DV: shall not be declared > 2% DV: round to nearest 10 mcg RAE and round to nearest % DV | D27: <2% DV: shall not be declared > 2% DV: round to nearest 1 mg and round to nearest % DV | E27: <2% DV: shall not be declared > 2% DV: round to nearest 0.1 mcg and round to nearest % DV | F27: < 0.5g - express as 0 < 1g - express as "contains less than 1g" or "less than 1g" ≥1g - express to nearest 1g increment Insignificant amount is < 0.5g
B28: Reco. | C28: none | D28: none | E28: 0 | F28: 0g
A30: Third Group - NMT 120% of Label | C30: Total Fat | D30: Saturated Fat | E30: Trans Fat | F30: Cholesterol
B31: Totals | C31: {=INDIRECT("'"&D2&"'!G8")} -> 0.037341652 | D31: {=INDIRECT("'"&D2&"'!H8")} -> 0.0061942595 | E31: {=INDIRECT("'"&D2&"'!I8")} -> 0 | F31: {=INDIRECT("'"&D2&"'!J8")} -> 0
B32: RDI | C32: 78 | D32: 20 | E32: NA | F32: 300 mg
B33: %RDI | C33: NA | D33: NA | E33: NA | F33: NA
C34: < 0.5g - express as 0 < 5 g - nearest 0.5 g increment > 5 g: nearest 1 g increment | D34: < 0.5g - express as 0 < 5 g - nearest 0.5 g increment > 5 g: nearest 1 g increment | E34: < 0.5g - express as 0 < 5 g - nearest 0.5 g increment > 5 g: nearest 1 g increment | F34: < 2mg: express as 0 2-5 mg: "less than 5 mg" > 5 mg: 5 mg increment
B35: Reco. | C35: none | D35: none | E35: none | F35: none
A37: Third Group - NMT 120% of Label | C37: {=INDIRECT("'"&D2&"'!E13")} -> Calories (US Rules) | D37: Calories from Fat | E37: {=INDIRECT("'"&D2&"'!N13")} -> Sugar | F37: {=INDIRECT("'"&D2&"'!O13")} -> Added Sugars | G37: {=INDIRECT("'"&D2&"'!R13")} -> Sodium
B38: Totals | C38: =C7 -> 15.244346 | D38: {=INDIRECT("'"&D2&"'!F8")} -> 0.18050564 | E38: {=INDIRECT("'"&D2&"'!N8")} -> 0.11418553 | F38: {=INDIRECT("'"&D2&"'!O8")} -> 0.045741932 | G38: {=INDIRECT("'"&D2&"'!R8")} -> 5.1773643
C39: NA | D39: NA | E39: NA | F39: 50 | G39: 2300
B40: %RDI | C40: NA | D40: NA | E40: NA | F40: =F38/F39 -> 0.00091483864 | G40: =G38/G39 -> 0.002251028
C41: < 5 cal - express as 0 ≤ 50 cal - express to nearest 5 cal increment > 50 cal - express to nearest 10 cal increment Insignificant amount is < 5 cal | D41: Not required to be declared | E41: < 0.5g - express as 0 < 1g - express as "contains less than 1g" or "less than 1g" ≥1g - express to nearest 1g increment Insignificant amount is < 0.5g | F41: < 0.5g - express as 0 < 1g - express as "contains less than 1g" or "less than 1g" ≥1g - express to nearest 1g increment Insignificant amount is < 0.5g | G41: < 5mg - express as 0 5-140mg - express to nearest 5mg increment > 140mg - express to nearest 10mg increment Insignificant amount is < 5mg
B42: Reco. | C42: 15kCal | D42: none | E42: 0 | F42: 0 | G42: 5mg
A50: Test Results from Eurofins 2/5/2025
A51: Eurofins samples number | B51: 14917322
B52: per 100g | D52: per dose (5.8g) | F52: Calculated(above)
A53: Calories (US Rules) | B53: 238 | D53: =(5.8/100)*B53 -> 13.804 | F53: =C42 -> 15kCal
...

Sheet Formulation Saguaro
B1: Edited/created on | C1: 46078 | D1: By | E1: Brooke Baker | F1: for | G1: Project 5-way
B2: Pick list items in blue
B3: edit yellow/orange cells
B4: green are results
B5: Product | C5: GCAS | D5: Saguaro
B6: Smooth Texture Sugar Free Orange Natural Dyes | C6: 5.8272 | D6: =C6*2 -> 11.6544
B7: DRIVER (g weight) | C7: 6.6 | E7: US rules (C) with sol. Fiber
B8: Total = | C8: =SUM(C14:C34) -> 0.9999 | D8: =SUM(D14:D21) -> 6.59934 | E8: ='Nutrition STOF'!C7 -> 30.349742 | F8: =SUM(F14:F34) -> 0.16048278 | G8: =SUM(G14:G34) -> 0.037502916 | H8: =SUM(H14:H34) -> 0.0061638456 | I8: =SUM(I14:I34) -> 0 | J8: =SUM(J14:J34) -> 0 | K8: =SUM(K14:K34) -> 5.9349609 | L8: =SUM(L14:L34) -> 3.1116281 | M8: =SUM(M14:M34) -> 2.6177778 | ... W8: =SUM(W14:W34) -> 0.084371272
E9: add g, mg, IU, ncg / 100 g row
B10: servings | C10: 2 | D10: =C6*2 -> 11.6544 | E10: =E8*$C$10 -> 60.699483 | F10: =F8*$C$10 -> 0.32096555 | G10: =G8*$C$10 -> 0.075005832 | H10: =H8*$C$10 -> 0.012327691 | I10: =I8*$C$10 -> 0 | J10: =J8*$C$10 -> 0 | K10: =K8*$C$10 -> 11.869922 | L10: =L8*$C$10 -> 6.2232562 | ... W10: =W8*$C$10 -> 0.16874254
C12: =SUM(C14:C34) -> 0.9999
B13: Ingredient | C13: % w/w | D13: Dose wt | E13: Calories (US Rules) | F13: Calories from Fat | G13: Total Fat | H13: Saturated Fat | I13: Trans Fat | J13: Cholesterol | K13: Total carbohydrate | L13: Total dietary fiber | M13: Soluble fiber | N13: Sugar | O13: Added Sugars | P13: Iron | Q13: Potassium | R13: Sodium | S13: Calcium | T13: Vitamin A | U13: Vitamin C | V13: Vitamin D | W13: Protein
A14: 1 | B14: Psyllium | C14: 0.5626 | D14: =C14*$C$7 -> 3.71316 | E14: =VLOOKUP($B14,Ingredients!$A:$W,5,FALSE)*$D14/100 -> 13.397081 | F14: =VLOOKUP($B14,Ingredients!$A:$W,6,FALSE)*$D14/100 -> 0.16048278 | G14: =VLOOKUP($B14,Ingredients!$A:$W,7,FALSE)*$D14/100 -> 0.037502916 | H14: =VLOOKUP($B14,Ingredients!$A:$W,8,FALSE)*$D14/100 -> 0.0061638456 | I14: =VLOOKUP($B14,Ingredients!$A:$W,9,FALSE)*$D14/100 -> 0 | J14: =VLOOKUP($B14,Ingredients!$A:$W,10,FALSE)*$D14/100 -> 0 | K14: =VLOOKUP($B14,Ingredients!$A:$W,11,FALSE)*$D14/100 -> 3.2304492 | L14: =VLOOKUP($B14,Ingredients!$A:$W,12,FALSE)*$D14/100 -> 3.1116281 | M14: =VLOOKUP($B14,Ingredients!$A:$W,13,FALSE)*$D14/100 -> 2.6177778 | N14: =VLOOKUP($B14,Ingredients!$A:$W,14,FALSE)*$D14/100 -> 0.00371316 | O14: =VLOOKUP($B14,Ingredients!$A:$W,15,FALSE)*$D14/100 -> 0 | P14: =VLOOKUP($B14,Ingredients!$A:$W,16,FALSE)*$D14/100 -> 0.28962648 | Q14: =VLOOKUP($B14,Ingredients!$A:$W,17,FALSE)*$D14/100 -> 31.450465 | R14: =VLOOKUP($B14,Ingredients!$A:$W,18,FALSE)*$D14/100 -> 2.6122081 | S14: =VLOOKUP($B14,Ingredients!$A:$W,19,FALSE)*$D14/100 -> 6.5043424 | T14: =VLOOKUP($B14,Ingredients!$A:$W,20,FALSE)*$D14/100 -> 0 | U14: =VLOOKUP($B14,Ingredients!$A:$W,21,FALSE)*$D14/100 -> 0 | V14: =VLOOKUP($B14,Ingredients!$A:$W,22,FALSE)*$D14/100 -> 0 | W14: =VLOOKUP($B14,Ingredients!$A:$W,23,FALSE)*$D14/100 -> 0.078013492
A15: 2 | B15: Maltodextrin | C15: 0.3211 | D15: =C15*$C$7 -> 2.11926 | E15: =VLOOKUP($B15,Ingredients!$A:$W,5,FALSE)*$D15/100 -> 8.0108028 | F15: =VLOOKUP($B15,Ingredients!$A:$W,6,FALSE)*$D15/100 -> 0 | G15: =VLOOKUP($B15,Ingredients!$A:$W,7,FALSE)*$D15/100 -> 0 | H15: =VLOOKUP($B15,Ingredients!$A:$W,8,FALSE)*$D15/100 -> 0 | I15: =VLOOKUP($B15,Ingredients!$A:$W,9,FALSE)*$D15/100 -> 0 | J15: =VLOOKUP($B15,Ingredients!$A:$W,10,FALSE)*$D15/100 -> 0 | K15: =VLOOKUP($B15,Ingredients!$A:$W,11,FALSE)*$D15/100 -> 1.9963429 | L15: =VLOOKUP($B15,Ingredients!$A:$W,12,FALSE)*$D15/100 -> 0 | M15: =VLOOKUP($B15,Ingredients!$A:$W,13,FALSE)*$D15/100 -> 0 | N15: =VLOOKUP($B15,Ingredients!$A:$W,14,FALSE)*$D15/100 -> 0.0741741 | O15: =VLOOKUP($B15,Ingredients!$A:$W,15,FALSE)*$D15/100 -> 0 | P15: =VLOOKUP($B15,Ingredients!$A:$W,16,FALSE)*$D15/100 -> 0.0105963 | Q15: =VLOOKUP($B15,Ingredients!$A:$W,17,FALSE)*$D15/100 -> 0 | R15: =VLOOKUP($B15,Ingredients!$A:$W,18,FALSE)*$D15/100 -> 3.17889 | S15: =VLOOKUP($B15,Ingredients!$A:$W,19,FALSE)*$D15/100 -> 0.211926 | T15: =VLOOKUP($B15,Ingredients!$A:$W,20,FALSE)*$D15/100 -> 0 | U15: =VLOOKUP($B15,Ingredients!$A:$W,21,FALSE)*$D15/100 -> 0 | V15: =VLOOKUP($B15,Ingredients!$A:$W,22,FALSE)*$D15/100 -> 0 | W15: =VLOOKUP($B15,Ingredients!$A:$W,23,FALSE)*$D15/100 -> 0.00635778
A16: 3 | B16: Citric Acid Anhydrous | C16: 0.0854 | D16: =C16*$C$7 -> 0.56364 | E16: =VLOOKUP($B16,Ingredients!$A:$W,5,FALSE)*$D16/100 -> 1.3921908 | F16: =VLOOKUP($B16,Ingredients!$A:$W,6,FALSE)*$D16/100 -> 0 | G16: =VLOOKUP($B16,Ingredients!$A:$W,7,FALSE)*$D16/100 -> 0 | H16: =VLOOKUP($B16,Ingredients!$A:$W,8,FALSE)*$D16/100 -> 0 | I16: =VLOOKUP($B16,Ingredients!$A:$W,9,FALSE)*$D16/100 -> 0 | J16: =VLOOKUP($B16,Ingredients!$A:$W,10,FALSE)*$D16/100 -> 0 | K16: =VLOOKUP($B16,Ingredients!$A:$W,11,FALSE)*$D16/100 -> 0.56053998 | L16: =VLOOKUP($B16,Ingredients!$A:$W,12,FALSE)*$D16/100 -> 0 | M16: =VLOOKUP($B16,Ingredients!$A:$W,13,FALSE)*$D16/100 -> 0 | N16: =VLOOKUP($B16,Ingredients!$A:$W,14,FALSE)*$D16/100 -> 0 | O16: =VLOOKUP($B16,Ingredients!$A:$W,15,FALSE)*$D16/100 -> 0 | P16: =VLOOKUP($B16,Ingredients!$A:$W,16,FALSE)*$D16/100 -> 0 | Q16: =VLOOKUP($B16,Ingredients!$A:$W,17,FALSE)*$D16/100 -> 0.00169092 | R16: =VLOOKUP($B16,Ingredients!$A:$W,18,FALSE)*$D16/100 -> 0.00169092 | S16: =VLOOKUP($B16,Ingredients!$A:$W,19,FALSE)*$D16/100 -> 0.00112728 | T16: =VLOOKUP($B16,Ingredients!$A:$W,20,FALSE)*$D16/100 -> 0 | U16: =VLOOKUP($B16,Ingredients!$A:$W,21,FALSE)*$D16/100 -> 0 | V16: =VLOOKUP($B16,Ingredients!$A:$W,22,FALSE)*$D16/100 -> 0 | W16: =VLOOKUP($B16,Ingredients!$A:$W,23,FALSE)*$D16/100 -> 0
A17: 4 | B17: Stevia | C17: 0.0075 | D17: =C17*$C$7 -> 0.0495 | E17: =VLOOKUP($B17,Ingredients!$A:$W,5,FALSE)*$D17/100 -> 0 | F17: =VLOOKUP($B17,Ingredients!$A:$W,6,FALSE)*$D17/100 -> 0 | G17: =VLOOKUP($B17,Ingredients!$A:$W,7,FALSE)*$D17/100 -> 0 | H17: =VLOOKUP($B17,Ingredients!$A:$W,8,FALSE)*$D17/100 -> 0 | I17: =VLOOKUP($B17,Ingredients!$A:$W,9,FALSE)*$D17/100 -> 0 | J17: =VLOOKUP($B17,Ingredients!$A:$W,10,FALSE)*$D17/100 -> 0 | K17: =VLOOKUP($B17,Ingredients!$A:$W,11,FALSE)*$D17/100 -> 0 | L17: =VLOOKUP($B17,Ingredients!$A:$W,12,FALSE)*$D17/100 -> 0 | M17: =VLOOKUP($B17,Ingredients!$A:$W,13,FALSE)*$D17/100 -> 0 | N17: =VLOOKUP($B17,Ingredients!$A:$W,14,FALSE)*$D17/100 -> 0 | O17: =VLOOKUP($B17,Ingredients!$A:$W,15,FALSE)*$D17/100 -> 0 | P17: =VLOOKUP($B17,Ingredients!$A:$W,16,FALSE)*$D17/100 -> 0.000792 | Q17: =VLOOKUP($B17,Ingredients!$A:$W,17,FALSE)*$D17/100 -> 0.00198 | R17: =VLOOKUP($B17,Ingredients!$A:$W,18,FALSE)*$D17/100 -> 0.007425 | S17: =VLOOKUP($B17,Ingredients!$A:$W,19,FALSE)*$D17/100 -> 0 | T17: =VLOOKUP($B17,Ingredients!$A:$W,20,FALSE)*$D17/100 -> 0 | U17: =VLOOKUP($B17,Ingredients!$A:$W,21,FALSE)*$D17/100 -> 0 | V17: =VLOOKUP($B17,Ingredients!$A:$W,22,FALSE)*$D17/100 -> 0 | W17: =VLOOKUP($B17,Ingredients!$A:$W,23,FALSE)*$D17/100 -> 0
